[2025-08-24T14:53:19.322+0000] {local_task_job_runner.py:120} INFO - ::group::Pre task execution logs
[2025-08-24T14:53:19.361+0000] {taskinstance.py:2073} INFO - Dependencies all met for dep_context=non-requeueable deps ti=<TaskInstance: customer_churn_pipeline.ingest_data manual__2025-08-24T14:53:16.893664+00:00 [queued]>
[2025-08-24T14:53:19.368+0000] {taskinstance.py:2073} INFO - Dependencies all met for dep_context=requeueable deps ti=<TaskInstance: customer_churn_pipeline.ingest_data manual__2025-08-24T14:53:16.893664+00:00 [queued]>
[2025-08-24T14:53:19.368+0000] {taskinstance.py:2303} INFO - Starting attempt 1 of 3
[2025-08-24T14:53:19.378+0000] {taskinstance.py:2327} INFO - Executing <Task(PythonOperator): ingest_data> on 2025-08-24 14:53:16.893664+00:00
[2025-08-24T14:53:19.393+0000] {standard_task_runner.py:63} INFO - Started process 215 to run task
[2025-08-24T14:53:19.396+0000] {standard_task_runner.py:90} INFO - Running: ['***', 'tasks', 'run', 'customer_churn_pipeline', 'ingest_data', 'manual__2025-08-24T14:53:16.893664+00:00', '--job-id', '185', '--raw', '--subdir', 'DAGS_FOLDER/***_dag.py', '--cfg-path', '/tmp/tmpnhd6_pdt']
[2025-08-24T14:53:19.399+0000] {standard_task_runner.py:91} INFO - Job 185: Subtask ingest_data
[2025-08-24T14:53:19.450+0000] {task_command.py:426} INFO - Running <TaskInstance: customer_churn_pipeline.ingest_data manual__2025-08-24T14:53:16.893664+00:00 [running]> on host e7c10817c3ee
[2025-08-24T14:53:19.532+0000] {taskinstance.py:2644} INFO - Exporting env vars: AIRFLOW_CTX_DAG_EMAIL='admin@company.com' AIRFLOW_CTX_DAG_OWNER='data-team' AIRFLOW_CTX_DAG_ID='customer_churn_pipeline' AIRFLOW_CTX_TASK_ID='ingest_data' AIRFLOW_CTX_EXECUTION_DATE='2025-08-24T14:53:16.893664+00:00' AIRFLOW_CTX_TRY_NUMBER='1' AIRFLOW_CTX_DAG_RUN_ID='manual__2025-08-24T14:53:16.893664+00:00'
[2025-08-24T14:53:19.533+0000] {taskinstance.py:430} INFO - ::endgroup::
[2025-08-24T14:53:19.553+0000] {logging_mixin.py:188} WARNING - 2025-08-24 14:53:19,553 - DataIngestion - INFO - Starting customer data ingestion
[2025-08-24T14:53:19.553+0000] {airflow_dag.py:82} INFO - Starting customer data ingestion
[2025-08-24T14:53:19.553+0000] {logging_mixin.py:188} WARNING - 2025-08-24 14:53:19,553 - DataGenerator - INFO - Fetching customer records
[2025-08-24T14:53:19.553+0000] {airflow_dag.py:82} INFO - Fetching customer records
[2025-08-24T14:53:19.562+0000] {logging_mixin.py:188} WARNING - 2025-08-24 14:53:19,562 - DataIngestion - ERROR - Customer data ingestion failed: Execution failed on sql 'SELECT * FROM customers': no such table: customers
[2025-08-24T14:53:19.562+0000] {airflow_dag.py:85} ERROR - Customer data ingestion failed: Execution failed on sql 'SELECT * FROM customers': no such table: customers
[2025-08-24T14:53:19.563+0000] {logging_mixin.py:188} WARNING - 2025-08-24 14:53:19,563 - PipelineMonitor - INFO - Logged metrics for data_ingestion: failed in 0.01s
[2025-08-24T14:53:19.563+0000] {airflow_dag.py:82} INFO - Logged metrics for data_ingestion: failed in 0.01s
[2025-08-24T14:53:19.564+0000] {logging_mixin.py:188} WARNING - 2025-08-24 14:53:19,563 - PipelineMonitor - INFO - Logged metrics for data_ingestion: failed in 0.01s
[2025-08-24T14:53:19.563+0000] {airflow_dag.py:82} INFO - Logged metrics for data_ingestion: failed in 0.01s
[2025-08-24T14:53:19.564+0000] {taskinstance.py:441} INFO - ::group::Post task execution logs
[2025-08-24T14:53:19.564+0000] {taskinstance.py:2890} ERROR - Task failed with exception
Traceback (most recent call last):
  File "/home/airflow/.local/lib/python3.12/site-packages/airflow/models/taskinstance.py", line 465, in _execute_task
    result = _execute_callable(context=context, **execute_callable_kwargs)
             ^^^^^^^^^^^^^^^^^^^^^^^^^^^^^^^^^^^^^^^^^^^^^^^^^^^^^^^^^^^^^
  File "/home/airflow/.local/lib/python3.12/site-packages/airflow/models/taskinstance.py", line 432, in _execute_callable
    return execute_callable(context=context, **execute_callable_kwargs)
           ^^^^^^^^^^^^^^^^^^^^^^^^^^^^^^^^^^^^^^^^^^^^^^^^^^^^^^^^^^^^
  File "/home/airflow/.local/lib/python3.12/site-packages/airflow/models/baseoperator.py", line 400, in wrapper
    return func(self, *args, **kwargs)
           ^^^^^^^^^^^^^^^^^^^^^^^^^^^
  File "/home/airflow/.local/lib/python3.12/site-packages/airflow/operators/python.py", line 235, in execute
    return_value = self.execute_callable()
                   ^^^^^^^^^^^^^^^^^^^^^^^
  File "/home/airflow/.local/lib/python3.12/site-packages/airflow/operators/python.py", line 252, in execute_callable
    return self.python_callable(*self.op_args, **self.op_kwargs)
           ^^^^^^^^^^^^^^^^^^^^^^^^^^^^^^^^^^^^^^^^^^^^^^^^^^^^^
  File "/opt/airflow/dags/airflow_dag.py", line 777, in ingest_data
    raise Exception("Data ingestion failed")
Exception: Data ingestion failed
[2025-08-24T14:53:19.579+0000] {taskinstance.py:1205} INFO - Marking task as UP_FOR_RETRY. dag_id=customer_churn_pipeline, task_id=ingest_data, execution_date=20250824T145316, start_date=20250824T145319, end_date=20250824T145319
[2025-08-24T14:53:19.589+0000] {standard_task_runner.py:110} ERROR - Failed to execute job 185 for task ingest_data (Data ingestion failed; 215)
[2025-08-24T14:53:19.618+0000] {local_task_job_runner.py:240} INFO - Task exited with return code 1
[2025-08-24T14:53:19.671+0000] {taskinstance.py:3482} INFO - 0 downstream tasks scheduled from follow-on schedule check
[2025-08-24T14:53:19.674+0000] {local_task_job_runner.py:222} INFO - ::endgroup::
